Workbook

Sheet personaggi
A1: nome | B1: possibile starter | C1: prezzo | D1: tier | E1: saga | F1: razza | G1: negoziante | H1: cattivo | I1: persona | J1: barre | K1: potenza | L1: velocità | M1: gigante | N1: mossa 1 | O1: mossa 2 | P1: mossa finale | Q1: si trasforma in
A2: Son Goku (inizio) | B2: sì | C2: =IF(INDEX(tier!$B$2:$B$20,MATCH(D2,tier!$A$2:$A$20,0))="","",INDEX(tier!$B$2:$B$20,MATCH(D2,tier!$A$2:$A$20,0))) | D2: C+ | E2: Saiyan | F2: Saiyan | G2: - | H2: - | I2: Son Goku (inizio) | J2: 4 | K2: 3 | L2: 3 | M2: - | N2: Kamehameha (onda) | O2: Kaio-ken Attack (impeto) | P2: Spirit Bomb (onda)
A3: Son Goku (metà) | B3: - | C3: =IF(INDEX(tier!$B$2:$B$20,MATCH(D3,tier!$A$2:$A$20,0))="","",INDEX(tier!$B$2:$B$20,MATCH(D3,tier!$A$2:$A$20,0))) | D3: B+ | E3: Freezer | F3: Saiyan | G3: - | H3: - | I3: Son Goku (metà) | J3: 4 | K3: 3 | L3: 3 | M3: - | N3: x20 Kaio-ken Kamehameha (onda) | O3: Meteor Combination (impeto) | P3: Spirit Bomb (onda) | Q3: Son Goku (metà) SSJ
A4: Son Goku (metà) SSJ | B4: - | C4: =IF(INDEX(tier!$B$2:$B$20,MATCH(D4,tier!$A$2:$A$20,0))="","",INDEX(tier!$B$2:$B$20,MATCH(D4,tier!$A$2:$A$20,0))) | D4: A | E4: Freezer | F4: Saiyan | G4: - | H4: - | I4: Son Goku (metà) | J4: 4 | K4: 3 | L4: 3 | M4: - | N4: Super Kamehameha (onda) | O4: Meteor Smash (impeto) | P4: Angry Kamehameha (onda)
A5: Son Goku (fine) | B5: - | C5: =IF(INDEX(tier!$B$2:$B$20,MATCH(D5,tier!$A$2:$A$20,0))="","",INDEX(tier!$B$2:$B$20,MATCH(D5,tier!$A$2:$A$20,0))) | D5: A | E5: Majin Bu | F5: Saiyan | G5: - | H5: - | I5: Son Goku (fine) | J5: 4 | K5: 3 | L5: 3 | M5: - | N5: Kamehameha (onda) | O5: Meteor Smash (impeto) | P5: Super Spirit Bomb (onda) | Q5: Son Goku (fine) SSJ
A6: Son Goku (fine) SSJ | B6: - | C6: =IF(INDEX(tier!$B$2:$B$20,MATCH(D6,tier!$A$2:$A$20,0))="","",INDEX(tier!$B$2:$B$20,MATCH(D6,tier!$A$2:$A$20,0))) | D6: A+ | E6: Majin Bu | F6: Saiyan | G6: - | H6: - | I6: Son Goku (fine) | J6: 4 | K6: 3 | L6: 3 | M6: - | N6: Super Kamehameha (onda) | O6: Super Energy Wave Volley (impeto) | P6: Instant Kamehameha (onda) | Q6: Son Goku (fine) SSJ2
A7: Son Goku (fine) SSJ2 | B7: - | C7: =IF(INDEX(tier!$B$2:$B$20,MATCH(D7,tier!$A$2:$A$20,0))="","",INDEX(tier!$B$2:$B$20,MATCH(D7,tier!$A$2:$A$20,0))) | D7: S | E7: Majin Bu | F7: Saiyan | G7: - | H7: - | I7: Son Goku (fine) | J7: 4 | K7: 3 | L7: 3 | M7: - | N7: Kamehameha (onda) | O7: Meteor Crash (impeto) | P7: Super Kamehameha (onda) | Q7: Son Goku (fine) SSJ3
A8: Son Goku (fine) SSJ3 | B8: - | C8: =IF(INDEX(tier!$B$2:$B$20,MATCH(D8,tier!$A$2:$A$20,0))="","",INDEX(tier!$B$2:$B$20,MATCH(D8,tier!$A$2:$A$20,0))) | D8: S+ | E8: Majin Bu | F8: Saiyan | G8: - | H8: - | I8: Son Goku (fine) | J8: 4 | K8: 3 | L8: 3 | M8: - | N8: Super Kamehameha (onda) | O8: Super Explosive Wave (onda) | P8: Dragon Fist (impeto, giganti)
A9: Son Goku (GT) | B9: - | C9: =IF(INDEX(tier!$B$2:$B$20,MATCH(D9,tier!$A$2:$A$20,0))="","",INDEX(tier!$B$2:$B$20,MATCH(D9,tier!$A$2:$A$20,0))) | D9: B+ | E9: GT | F9: Saiyan | G9: - | H9: - | I9: Son Goku (GT) | J9: 4 | K9: 3 | L9: 3 | M9: - | N9: Kamehameha (onda) | O9: Dragon Fist (impeto, giganti) | P9: Spirit Bomb (onda) | Q9: Son Goku (GT) SSJ
A10: Son Goku (GT) SSJ | B10: - | C10: =IF(INDEX(tier!$B$2:$B$20,MATCH(D10,tier!$A$2:$A$20,0))="","",INDEX(tier!$B$2:$B$20,MATCH(D10,tier!$A$2:$A$20,0))) | D10: A+ | E10: GT | F10: Saiyan | G10: - | H10: - | I10: Son Goku (GT) | J10: 4 | K10: 3 | L10: 3 | M10: - | N10: Super Kamehameha (onda) | O10: Full Power Energy Blast Volley (impeto) | P10: Super Explosive Wave (onda) | Q10: Son Goku (GT) SSJ3
A11: Son Goku (GT) SSJ3 | B11: - | C11: =IF(INDEX(tier!$B$2:$B$20,MATCH(D11,tier!$A$2:$A$20,0))="","",INDEX(tier!$B$2:$B$20,MATCH(D11,tier!$A$2:$A$20,0))) | D11: S | E11: GT | F11: Saiyan | G11: - | H11: - | I11: Son Goku (GT) | J11: 4 | K11: 3 | L11: 3 | M11: - | N11: Super Kamehameha (onda) | O11: Full Power Energy Blast Volley (onda) | P11: Dragon Fist (impeto, giganti) | Q11: Son Goku SSJ4
A12: Son Goku SSJ4 | B12: - | C12: =IF(INDEX(tier!$B$2:$B$20,MATCH(D12,tier!$A$2:$A$20,0))="","",INDEX(tier!$B$2:$B$20,MATCH(D12,tier!$A$2:$A$20,0))) | D12: SS | E12: GT | F12: Saiyan | G12: - | H12: - | I12: Son Goku (GT) | J12: 4 | K12: 3 | L12: 3 | M12: - | N12: 10x Kamehameha (onda) | O12: Meteor Crash (impeto) | P12: Dragon Fist (impeto, giganti)
A13: Son Goku (bambino) | B13: sì | C13: =IF(INDEX(tier!$B$2:$B$20,MATCH(D13,tier!$A$2:$A$20,0))="","",INDEX(tier!$B$2:$B$20,MATCH(D13,tier!$A$2:$A$20,0))) | D13: C | E13: Dragon Ball | F13: Saiyan | G13: - | H13: - | I13: Son Goku (bambino) | J13: 3 | K13: 2 | L13: 4 | M13: - | N13: Kamehameha (onda) | O13: Counterattack! (impeto) | P13: Penetrate! (impeto, giganti) | Q13: Son Goku (bambino) Oozaru
A14: Son Goku (bambino) Oozaru | B14: - | C14: =IF(INDEX(tier!$B$2:$B$20,MATCH(D14,tier!$A$2:$A$20,0))="","",INDEX(tier!$B$2:$B$20,MATCH(D14,tier!$A$2:$A$20,0))) | D14: A- | E14: Dragon Ball | F14: Saiyan | G14: - | H14: - | I14: Son Goku (bambino) | J14: 5 | K14: 5 | L14: 1 | M14: sì | N14: Chou Makouhou (onda) | O14: Gigant Rock Throw (onda) | P14: Chou Makouhou Barrage (onda)
A15: Son Gohan (bambino) | B15: sì | C15: =IF(INDEX(tier!$B$2:$B$20,MATCH(D15,tier!$A$2:$A$20,0))="","",INDEX(tier!$B$2:$B$20,MATCH(D15,tier!$A$2:$A$20,0))) | D15: C | E15: Saiyan | F15: Ibrido Saiyan-terrestre | G15: - | H15: - | I15: Son Gohan (bambino) | J15: 3 | K15: 2 | L15: 4 | M15: - | N15: Masenko (onda) | O15: Gekiretsu Madan (onda) | P15: Bakuretsu Ranma (impeto)
A16: Son Gohan (ragazzo) | B16: - | C16: =IF(INDEX(tier!$B$2:$B$20,MATCH(D16,tier!$A$2:$A$20,0))="","",INDEX(tier!$B$2:$B$20,MATCH(D16,tier!$A$2:$A$20,0))) | D16: B+ | E16: Cell | F16: Ibrido Saiyan-terrestre | G16: - | H16: - | I16: Son Gohan (ragazzo) | J16: 4 | K16: 3 | L16: 3 | M16: - | N16: Super Masenko (onda) | O16: Gekiretsu Madan (onda) | P16: Super Kamehameha (onda) | Q16: Son Gohan (ragazzo) SSJ
A17: Son Gohan (ragazzo) SSJ | B17: - | C17: =IF(INDEX(tier!$B$2:$B$20,MATCH(D17,tier!$A$2:$A$20,0))="","",INDEX(tier!$B$2:$B$20,MATCH(D17,tier!$A$2:$A$20,0))) | D17: A+ | E17: Cell | F17: Ibrido Saiyan-terrestre | G17: - | H17: - | I17: Son Gohan (ragazzo) | J17: 4 | K17: 3 | L17: 3 | M17: - | N17: Super Masenko (onda) | O17: Chou Maretsugeki (impeto) | P17: Super Kamehameha (onda) | Q17: Son Gohan (ragazzo) SSJ2
A18: Son Gohan (ragazzo) SSJ2 | B18: - | C18: =IF(INDEX(tier!$B$2:$B$20,MATCH(D18,tier!$A$2:$A$20,0))="","",INDEX(tier!$B$2:$B$20,MATCH(D18,tier!$A$2:$A$20,0))) | D18: S | E18: Cell | F18: Ibrido Saiyan-terrestre | G18: - | H18: - | I18: Son Gohan (ragazzo) | J18: 4 | K18: 3 | L18: 3 | M18: - | N18: Super Kamehameha (onda) | O18: Gekiretsu Madan (onda) | P18: Father-Son Kamehameha (onda)
A19: Son Gohan | B19: - | C19: =IF(INDEX(tier!$B$2:$B$20,MATCH(D19,tier!$A$2:$A$20,0))="","",INDEX(tier!$B$2:$B$20,MATCH(D19,tier!$A$2:$A$20,0))) | D19: A | E19: Majin Bu | F19: Ibrido Saiyan-terrestre | G19: - | H19: - | I19: Son Gohan | J19: 4 | K19: 3 | L19: 3 | M19: - | N19: Explosive Madan (onda) | O19: Full Power Energy Blast Volley (onda) | P19: Super Kamehameha (onda) | Q19: Son Gohan SSJ
A20: Son Gohan SSJ | B20: - | C20: =IF(INDEX(tier!$B$2:$B$20,MATCH(D20,tier!$A$2:$A$20,0))="","",INDEX(tier!$B$2:$B$20,MATCH(D20,tier!$A$2:$A$20,0))) | D20: A+ | E20: Majin Bu | F20: Ibrido Saiyan-terrestre | G20: - | H20: - | I20: Son Gohan | J20: 4 | K20: 3 | L20: 3 | M20: - | N20: Explosive Madan (onda) | O20: Full Power Energy Blast Volley (onda) | P20: Bros. Kamehameha (onda) | Q20: Son Gohan SSJ2
A21: Son Gohan SSJ2 | B21: - | C21: =IF(INDEX(tier!$B$2:$B$20,MATCH(D21,tier!$A$2:$A$20,0))="","",INDEX(tier!$B$2:$B$20,MATCH(D21,tier!$A$2:$A$20,0))) | D21: S | E21: Majin Bu | F21: Ibrido Saiyan-terrestre | G21: - | H21: - | I21: Son Gohan | J21: 4 | K21: 3 | L21: 3 | M21: - | N21: Super Explosive Madan (onda) | O21: Full Power Energy Barrage Wave (onda) | P21: Super Kamehameha (onda)
A22: Great Saiyaman | B22: - | C22: =IF(INDEX(tier!$B$2:$B$20,MATCH(D22,tier!$A$2:$A$20,0))="","",INDEX(tier!$B$2:$B$20,MATCH(D22,tier!$A$2:$A$20,0))) | D22: B | E22: Majin Bu | F22: Ibrido Saiyan-terrestre | G22: - | H22: - | I22: Great Saiyaman | J22: 4 | K22: 3 | L22: 3 | M22: - | N22: Super Explosive Wave (onda) | O22: Justice Slash (impeto) | P22: Justice Judgment (impeto)
A23: Son Gohan (Ultimate) | B23: - | C23: =IF(INDEX(tier!$B$2:$B$20,MATCH(D23,tier!$A$2:$A$20,0))="","",INDEX(tier!$B$2:$B$20,MATCH(D23,tier!$A$2:$A$20,0))) | D23: S+ | E23: Majin Bu | F23: Ibrido Saiyan-terrestre | G23: - | H23: - | I23: Son Gohan (Ultimate) | J23: 4 | K23: 3 | L23: 3 | M23: - | N23: Super Kamehameha (onda) | O23: Super Explosive Wave (onda) | P23: Burst Rush (impeto)
A24: Son Gohan (futuro) | B24: - | C24: =IF(INDEX(tier!$B$2:$B$20,MATCH(D24,tier!$A$2:$A$20,0))="","",INDEX(tier!$B$2:$B$20,MATCH(D24,tier!$A$2:$A$20,0))) | D24: B+ | E24: Film e speciali | F24: Ibrido Saiyan-terrestre | G24: - | H24: - | I24: Son Gohan (futuro) | J24: 4 | K24: 3 | L24: 3 | M24: - | N24: Masenko (onda) | O24: Super Explosive Wave (onda) | P24: Super Kamehameha (onda) | Q24: Son Gohan (futuro) SSJ
A25: Son Gohan (futuro) SSJ | B25: - | C25: =IF(INDEX(tier!$B$2:$B$20,MATCH(D25,tier!$A$2:$A$20,0))="","",INDEX(tier!$B$2:$B$20,MATCH(D25,tier!$A$2:$A$20,0))) | D25: A | E25: Film e speciali | F25: Ibrido Saiyan-terrestre | G25: - | H25: - | I25: Son Gohan (futuro) | J25: 4 | K25: 3 | L25: 3 | M25: - | N25: Gekiretsu Madan (onda) | O25: Special Beam Cannon (onda) | P25: Gekiretsu Ranbu (impeto)
A26: Son Goten | B26: - | C26: =IF(INDEX(tier!$B$2:$B$20,MATCH(D26,tier!$A$2:$A$20,0))="","",INDEX(tier!$B$2:$B$20,MATCH(D26,tier!$A$2:$A$20,0))) | D26: B | E26: Majin Bu | F26: Ibrido Saiyan-terrestre | G26: - | H26: - | I26: Son Goten | J26: 3 | K26: 2 | L26: 4 | M26: - | N26: Full Power Energy Blast Volley (onda) | O26: Assault! (impeto) | P26: Super Kamehameha (onda) | Q26: Son Goten SSJ
A27: Son Goten SSJ | B27: - | C27: =IF(INDEX(tier!$B$2:$B$20,MATCH(D27,tier!$A$2:$A$20,0))="","",INDEX(tier!$B$2:$B$20,MATCH(D27,tier!$A$2:$A$20,0))) | D27: A | E27: Majin Bu | F27: Ibrido Saiyan-terrestre | G27: - | H27: - | I27: Son Goten | J27: 3 | K27: 2 | L27: 4 | M27: - | N27: Kamehameha (onda) | O27: Assault! (impeto) | P27: Bros. Kamehameha (onda)
A28: Vegeta (scouter) | B28: - | C28: =IF(INDEX(tier!$B$2:$B$20,MATCH(D28,tier!$A$2:$A$20,0))="","",INDEX(tier!$B$2:$B$20,MATCH(D28,tier!$A$2:$A$20,0))) | D28: B | E28: Saiyan | F28: Saiyan | G28: - | H28: sì | I28: Vegeta (scouter) | J28: 4 | K28: 3 | L28: 3 | M28: - | N28: Galick Gun (onda) | O28: Final Galick Cannon (impeto) | P28: Dirty Fireworks (impeto) | Q28: Vegeta (scouter) Oozaru
A29: Vegeta (scouter) Oozaru | B29: - | C29: =IF(INDEX(tier!$B$2:$B$20,MATCH(D29,tier!$A$2:$A$20,0))="","",INDEX(tier!$B$2:$B$20,MATCH(D29,tier!$A$2:$A$20,0))) | D29: A | E29: Saiyan | F29: Saiyan | G29: - | H29: sì | I29: Vegeta (scouter) | J29: 5 | K29: 5 | L29: 1 | M29: sì | N29: Chou Makouhou (onda) | O29: Chou Makouhou Barrage (onda) | P29: Super Galick Gun (onda)
A30: Vegeta | B30: - | C30: =IF(INDEX(tier!$B$2:$B$20,MATCH(D30,tier!$A$2:$A$20,0))="","",INDEX(tier!$B$2:$B$20,MATCH(D30,tier!$A$2:$A$20,0))) | D30: B+ | E30: Cell | F30: Saiyan | G30: - | H30: - | I30: Vegeta | J30: 4 | K30: 3 | L30: 3 | M30: - | N30: Galick Gun (onda) | O30: Super Energy Wave Volley (onda) | P30: Super Explosive Wave (onda) | Q30: Vegeta SSJ
A31: Vegeta SSJ | B31: - | C31: =IF(INDEX(tier!$B$2:$B$20,MATCH(D31,tier!$A$2:$A$20,0))="","",INDEX(tier!$B$2:$B$20,MATCH(D31,tier!$A$2:$A$20,0))) | D31: A | E31: Cell | F31: Saiyan | G31: - | H31: - | I31: Vegeta | J31: 4 | K31: 3 | L31: 3 | M31: - | N31: Maximum Flasher (onda) | O31: Amazing Impact (impeto) | P31: Big Bang Attack (onda) | Q31: Super Vegeta
A32: Super Vegeta | B32: - | C32: =IF(INDEX(tier!$B$2:$B$20,MATCH(D32,tier!$A$2:$A$20,0))="","",INDEX(tier!$B$2:$B$20,MATCH(D32,tier!$A$2:$A$20,0))) | D32: A+ | E32: Cell | F32: Saiyan | G32: - | H32: - | I32: Vegeta | J32: 4 | K32: 3 | L32: 3 | M32: - | N32: Big Bang Attack (onda) | O32: Spirit Breaking Cannon (impeto) | P32: Final Flash (onda)
A33: Vegeta (seconda forma) | B33: - | C33: =IF(INDEX(tier!$B$2:$B$20,MATCH(D33,tier!$A$2:$A$20,0))="","",INDEX(tier!$B$2:$B$20,MATCH(D33,tier!$A$2:$A$20,0))) | D33: A | E33: Majin Bu | F33: Saiyan | G33: - | H33: - | I33: Vegeta (seconda forma) | J33: 4 | K33: 3 | L33: 3 | M33: - | N33: Galick Gun (onda) | O33: Super Energy Wave Volley (onda) | P33: Big Bang Attack (onda) | Q33: Vegeta (seconda forma) SSJ
A34: Vegeta (seconda forma) SSJ | B34: - | C34: =IF(INDEX(tier!$B$2:$B$20,MATCH(D34,tier!$A$2:$A$20,0))="","",INDEX(tier!$B$2:$B$20,MATCH(D34,tier!$A$2:$A$20,0))) | D34: A+ | E34: Majin Bu | F34: Saiyan | G34: - | H34: - | I34: Vegeta (seconda forma) | J34: 4 | K34: 3 | L34: 3 | M34: - | N34: Final Flash (onda) | O34: Super Energy Wave Volley (onda) | P34: Super Explosive Wave (onda) | Q34: Vegeta (seconda forma) SSJ2
A35: Vegeta (seconda forma) SSJ2 | B35: - | C35: =IF(INDEX(tier!$B$2:$B$20,MATCH(D35,tier!$A$2:$A$20,0))="","",INDEX(tier!$B$2:$B$20,MATCH(D35,tier!$A$2:$A$20,0))) | D35: S | E35: Majin Bu | F35: Saiyan | G35: - | H35: - | I35: Vegeta (seconda forma) | J35: 4 | K35: 3 | L35: 3 | M35: - | N35: Big Bang Attack (onda) | O35: Super Energy Wave Volley (onda) | P35: Final Flash (onda)
A36: Majin Vegeta | B36: - | C36: =IF(INDEX(tier!$B$2:$B$20,MATCH(D36,tier!$A$2:$A$20,0))="","",INDEX(tier!$B$2:$B$20,MATCH(D36,tier!$A$2:$A$20,0))) | D36: S | E36: Majin Bu | F36: Saiyan | G36: - | H36: sì | I36: Majin Vegeta | J36: 4 | K36: 3 | L36: 3 | M36: - | N36: Final Impact (onda) | O36: Big Bang Attack (onda) | P36: Final Explosion (onda)
A37: Vegeta SSJ4 | B37: - | C37: =IF(INDEX(tier!$B$2:$B$20,MATCH(D37,tier!$A$2:$A$20,0))="","",INDEX(tier!$B$2:$B$20,MATCH(D37,tier!$A$2:$A$20,0))) | D37: SS | E37: GT | F37: Saiyan | G37: - | H37: - | I37: Vegeta SSJ4 | J37: 4 | K37: 3 | L37: 3 | M37: - | N37: Final Flash (onda) | O37: Spirit Breaking Cannon (impeto) | P37: Final Shine Attack (onda)
A38: Trunks (spada) | B38: - | C38: =IF(INDEX(tier!$B$2:$B$20,MATCH(D38,tier!$A$2:$A$20,0))="","",INDEX(tier!$B$2:$B$20,MATCH(D38,tier!$A$2:$A$20,0))) | D38: B+ | E38: Cell | F38: Ibrido Saiyan-terrestre | G38: - | H38: - | I38: Trunks (spada) | J38: 4 | K38: 3 | L38: 3 | M38: - | N38: Finish Buster (onda) | O38: Burning Storm (onda) | P38: Lightning Sword Slash (onda) | Q38: Trunks (spada) SSJ
A39: Trunks (spada) SSJ | B39: - | C39: =IF(INDEX(tier!$B$2:$B$20,MATCH(D39,tier!$A$2:$A$20,0))="","",INDEX(tier!$B$2:$B$20,MATCH(D39,tier!$A$2:$A$20,0))) | D39: A | E39: Cell | F39: Ibrido Saiyan-terrestre | G39: - | H39: - | I39: Trunks (spada) | J39: 4 | K39: 3 | L39: 3 | M39: - | N39: Burning Attack (onda) | O39: Burning Storm (onda) | P39: Shining Sword Attack (impeto)
A40: Trunks | B40: - | C40: =IF(INDEX(tier!$B$2:$B$20,MATCH(D40,tier!$A$2:$A$20,0))="","",INDEX(tier!$B$2:$B$20,MATCH(D40,tier!$A$2:$A$20,0))) | D40: B+ | E40: Cell | F40: Ibrido Saiyan-terrestre | G40: - | H40: - | I40: Trunks | J40: 4 | K40: 3 | L40: 3 | M40: - | N40: Burning Attack (onda) | O40: High Speed Rush (impeto) | P40: Finish Buster (onda) | Q40: Trunks SSJ
...

Sheet tier
A1: tier | B1: prezzo | C1: in negozio
A2: SS+ | B2: 6000 | C2: sì
A3: SS | B3: 5500 | C3: sì
A4: SS- | B4: 5000 | C4: sì
A5: S+ | B5: 4200 | C5: sì
A6: S | B6: 3800 | C6: sì
A7: S- | B7: 3400 | C7: sì
A8: A+ | B8: 2800 | C8: sì
A9: A | B9: 2500 | C9: sì
A10: A- | B10: 2200 | C10: sì
A11: B+ | B11: 1900 | C11: sì
A12: B | B12: 1700 | C12: sì
A13: B- | B13: 1500 | C13: sì
A14: C+ | C14: no
A15: C | C15: no
A16: C- | C16: no
A17: D+ | C17: no
A18: D | C18: no
A19: D- | C19: no
A20: E | C20: no
A22: Prezzi indicativi (in blu): cambiali qui e il foglio 'personaggi' si aggiorna. I tier C, D, E non si vendono in negozio, quindi restano senza prezzo.

Sheet leggimi
A1: Catalogo personaggi · Budokai Tenkaichi 3
A2: Foglio 'personaggi': una riga per personaggio, 166 voci (ogni forma è una voce a sé, spec 002): 161 dal roster più 5 personaggi della storia non arruolabili (Kami, Karin, Bulma, Baba la Veggente, Chichi adulta).
A3: tier: da SS+ a D-, più E per Mr. Satan (proposta, modificabile). Senza tier = non arruolabile: personaggio della storia, per task o come negoziante (D-034). prezzo: calcolato dal tier tramite il foglio 'tier'; vuoto per i tier C, D, E, che non si vendono in negozio, e per chi non ha tier.
A4: possibile starter: sì per i tier da C a B-, - per tutti gli altri. Modificabile a mano.
A5: negoziante: sì per chi può fare il negoziante (Muten Roshi, Son Gohan (nonno), Kami, Karin, Bulma, Baba la Veggente), - per tutti gli altri. «Randomizza» sceglie i negozianti solo tra questi (spec 022).
A6: saga: valori usati → Dragon Ball, Saiyan, Freezer, Cell, Majin Bu, Film e speciali, GT, Extra.
A7: razza: Saiyan, Ibrido Saiyan-terrestre, Terrestre, Namecciano, Razza di Freezer, Androide, Bio-androide, Majin, Demone, Alieno e altre. Le trasformazioni hanno la razza del personaggio base.
A8: Esempio di riga: Krilin | sì | | C | Saiyan | Terrestre | -
A9: Per l'app: Salva con nome → CSV UTF-8, con il foglio 'personaggi' attivo.
A10: Fonte dell'elenco: roster di Budokai Tenkaichi 3, ricontrollato voce per voce su due elenchi completi (GameFAQs) e sulla Dragon Ball Wiki.
A11: cattivo (spec 027): «sì» per i cattivi. Chi non ha missioni sue nel catalogo delle missioni prende quelle del suo gruppo: cattivi, arruolabili o personaggi della storia.
A12: Colonna 'persona' (spec 039, D-064, cambia D-048): una persona è uno stesso personaggio con le sue trasformazioni, e il valore è il nome della sua prima forma (es. «Son Goku (metà)» per Goku (metà) e Goku (metà) SSJ; Goku (inizio), (metà) e (fine) sono tre persone). In una partita una persona sta in un solo posto. L'app la usa anche per non dare missioni «Vai da», «Batti» e «Porta» verso un'altra forma di chi le dà, e per non proporre due forme della stessa persona come starter a caso.
A13: Colonne della scheda di combattimento (spec 037, D-059), tutte facoltative: vuote valgono come la scheda normale. barre: da 3 a 5 (normale 4). potenza e velocità: da 1 a 5, potenza + velocità = 6 (normale 3 e 3). gigante: «sì» se gli impeti non lo colpiscono. mossa 1, mossa 2, mossa finale: nome e tipo, es. «Kamehameha (onda)», «Meteor Smash (impeto)»; «(impeto, giganti)» per un impeto che colpisce anche i giganti, come Penetrate!. Le mosse sono quelle di BT3 (due Blast 2 e la Ultimate), con i nomi inglesi del gioco: l'energia è un'onda, il fisico un impeto (D-057). si trasforma in: il nome della forma successiva, un personaggio di questa lista con un tier.
